<?xml version='1.0'?>
<sdf version='1.4'>
  <model name="my_robot">
  <static>false</static>
   <link name='chassis'>
            <pose>0 0 .1 0 0 0</pose>
 
            <collision name='collision'>
              <geometry>
                <box>
                  <size>.7 .4 .05</size>
                </box>
              </geometry>
            </collision>
 
            <visual name='visual'>
              <geometry>
                <box>
                  <size>.7 .4 .05</size>
                </box>
              </geometry>
            </visual>
     
    
    
          </link>
    <link name="front_left_wheel">
        <pose>0.25 0.25 0.1 0 1.5707 1.5707</pose>
        <collision name="collision">
          <geometry>
            <cylinder>
              <radius>.15</radius>
              <length>0.1</length>
            </cylinder>
          </geometry>
        </collision>
        <visual name="visual">
          <geometry>
            <cylinder>
              <radius>.15</radius>
              <length>0.1</length>
            </cylinder>
          </geometry>
        </visual>
        </link>

        <link name="front_right_wheel">
        <pose>0.25 -0.25 0.1 0 1.5707 1.5707</pose>
        <collision name="collision">
          <geometry>
            <cylinder>
              <radius>.15</radius>
              <length>.1</length>
            </cylinder>
          </geometry>
        </collision>
        <visual name="visual">
          <geometry>
            <cylinder>
              <radius>.15</radius>
              <length>.1</length>
            </cylinder>
          </geometry>
        </visual>
        </link>

        <link name="back_right_wheel">
        <pose>-0.25 -0.25 0.1 0 1.5707 1.5707</pose>
        <collision name="collision">
          <geometry>
            <cylinder>
              <radius>.15</radius>
              <length>.1</length>
            </cylinder>
          </geometry>
        </collision>
        <visual name="visual">
          <geometry>
            <cylinder>
              <radius>.15</radius>
              <length>.1</length>
            </cylinder>
          </geometry>
        </visual>
        </link>

        <link name="back_left_wheel">
        <pose>-0.25 0.25 0.1 0 1.5707 1.5707</pose>
        <collision name="collision">
          <geometry>
            <cylinder>
              <radius>.15</radius>
              <length>.1</length>
            </cylinder>
          </geometry>
        </collision>
        <visual name="visual">
          <geometry>
            <cylinder>
              <radius>.15</radius>
              <length>.1</length>
            </cylinder>
          </geometry>
        </visual>
        </link>

          <joint type="revolute" name="front_left_wheel_hinge">
        <pose>0 0 -0.03 0 0 0</pose>
        <child>front_left_wheel</child>
        <parent>chassis</parent>
        <axis>
          <xyz>0 1 0</xyz>
        </axis>
      </joint>
 
      <joint type="revolute" name="front_right_wheel_hinge">
        <pose>0 0 0.03 0 0 0</pose>
        <child>front_right_wheel</child>
        <parent>chassis</parent>
        <axis>
          <xyz>0 1 0</xyz>
        </axis>
      </joint>

      <joint type="revolute" name="back_left_wheel_hinge">
        <pose>0 0 -0.03 0 0 0</pose>
        <child>back_left_wheel</child>
        <parent>chassis</parent>
        <axis>
          <xyz>0 1 0</xyz>
        </axis>
      </joint>

      <joint type="revolute" name="back_right_wheel_hinge">
        <pose>0 0 0.03 0 0 0</pose>
        <child>back_right_wheel</child>
        <parent>chassis</parent>
        <axis>
          <xyz>0 1 0</xyz>
        </axis>
      </joint>
  </model>
</sdf>
